<?xml version="1.0"?>
<!-- Copyright (C) 2018, Tokyo Opensource Robotics Kyokai Association -->
<robot name="rv7fl" xmlns:xacro="http://www.ros.org/wiki/xacro">
  <link name="base_link">
  </link>

  <joint name="joint1" type="revolute">
    <parent link="base_link"/>
    <child link="link1"/>
    <origin xyz="0 0 0.4" rpy="0 0 0"/>
    <axis xyz="0 0 1"/>
    <dynamics damping="0.7"/>
    <limit upper="${240*pi/180}" lower="${-240*pi/180}" effort="10" velocity="${288*pi/180}" />
  </joint>

  <link name="link1">
  </link>

  <joint name="joint2" type="revolute">
    <parent link="link1"/>
    <child link="link2"/>
    <origin xyz="0 0 0" rpy="0 0 0"/>
    <axis xyz="0 1 0"/>
    <dynamics damping="0.7"/>
    <limit upper="${130*pi/180}" lower="${-110*pi/180}" effort="10" velocity="${321*pi/180}" />
  </joint>

  <link name="link2">
  </link>

  <joint name="joint3" type="revolute">
    <parent link="link2"/>
    <child link="link3"/>
    <origin xyz="0 0 0.435" rpy="0 0 0"/>
    <axis xyz="0 1 0"/>
    <dynamics damping="0.7"/>
    <limit upper="${162*pi/180}" lower="0.00" effort="10" velocity="${360*pi/180}" />
  </joint>

  <link name="link3">
  </link>

  <joint name="joint4" type="revolute">
    <parent link="link3"/>
    <child link="link4"/>
    <origin xyz="-0.05 0 0.47" rpy="0 0 0"/>
    <axis xyz="0 0 1"/>
    <dynamics damping="0.7"/>
    <limit upper="${200*pi/180}" lower="${-200*pi/180}" effort="10" velocity="${337*pi/180}" />
  </joint>

  <link name="link4">
  </link>

  <joint name="joint5" type="revolute">
    <parent link="link4"/>
    <child link="link5"/>
    <origin xyz="0 0 0" rpy="0 0 0"/>
    <axis xyz="0 1 0"/>
    <dynamics damping="0.7"/>
    <limit upper="${120*pi/180}" lower="${-120*pi/180}" effort="10" velocity="${450*pi/180}" />
  </joint>

  <link name="link5">
  </link>

  <joint name="joint6" type="revolute">
    <parent link="link5"/>
    <child link="link6"/>
    <origin xyz="0 0 0.085" rpy="0 0 0"/>
    <axis xyz="0 0 1"/>
    <dynamics damping="0.7"/>
    <limit upper="${360*pi/180}" lower="${-360*pi/180}" effort="10" velocity="${720*pi/180}" />
  </joint>

  <link name="link6"/>

  <link name="dummy1"/>
  <joint name="joint7" type="revolute">
    <parent link="base_link"/>
    <child link="dummy1"/>
    <origin xyz="0 0 0" rpy="0 0 0"/>
    <axis xyz="0 0 1"/>
    <limit upper="${240*pi/180}" lower="${-240*pi/180}" effort="10" velocity="${288*pi/180}" />
  </joint>

  <link name="dummy2"/>
  <joint name="joint8" type="revolute">
    <parent link="base_link"/>
    <child link="dummy2"/>
    <origin xyz="0 0 0" rpy="0 0 0"/>
    <axis xyz="0 0 1"/>
    <limit upper="${240*pi/180}" lower="${-240*pi/180}" effort="10" velocity="${288*pi/180}" />
  </joint>

</robot>
